#VRML_SIM R2023a utf8

EXTERNPROTO "https://raw.githubusercontent.com/cyberbotics/webots/R2023a/projects/objects/backgrounds/protos/TexturedBackgroundLight.proto"
EXTERNPROTO "https://raw.githubusercontent.com/cyberbotics/webots/R2023a/projects/objects/floors/protos/RectangleArena.proto"
EXTERNPROTO "https://raw.githubusercontent.com/cyberbotics/webots/R2023a/projects/appearances/protos/OsbWood.proto"

WorldInfo {
}
Viewpoint {
  orientation 0.14609989490013392 0.27390915193983095 -0.9505938129368255 1.0226665799547925
  position -1.1792438850562839 1.6458123657117048 1.2535174364118598
}
RectangleArena {
  translation -4.05924e-08 1.87709e-07 -0.04
  rotation 0.9774071921221089 0.21136504154655075 -2.343280460602283e-09 4.80123e-06
}
PointLight {
  attenuation 0 0 1
  intensity 0.6
  location 0 0.6 0
}
DEF SLOPE Solid {
  translation 0 0 0.15
  rotation 0 0.9992009587217893 0.039968038348871575 -0.5235996938995747
  children [
    Shape {
      appearance OsbWood {
        textureTransform TextureTransform {
        }
      }
      geometry DEF BOX0 Box {
        size 0.8 0.2 0.02
      }
    }
  ]
}
DEF MyBot Robot {
  translation -0.11084 -0.00354308 0.0935797
  rotation -0.03548218736753029 0.8593396940554272 0.5101728183668158 -0.68
  children [
    HingeJoint {
      jointParameters HingeJointParameters {
      }
      device [
        PositionSensor {
          name "right wheel sensor"
        }
        RotationalMotor {
          name "right wheel motor"
        }
      ]
      endPoint Solid {
        rotation 1 0 0 0
        children [
          Shape {
            appearance PBRAppearance {
              baseColor 1 0 0
              roughness 1
              metalness 0
            }
            geometry Cylinder {
              height 0.01
              radius 0.025
            }
          }
        ]
        name "solid(1)"
      }
    }
    HingeJoint {
      jointParameters HingeJointParameters {
        axis 0 1 0
        anchor 0 0 0.025
      }
      device [
        RotationalMotor {
          name "left wheel motor"
          consumptionFactor 70
        }
        PositionSensor {
          name "left wheel sensor"
        }
      ]
      endPoint Solid {
        rotation 0 1 0 0
        children [
          DEF WHEEL Transform {
            rotation 0.577883556445323 0.5770834407562329 -0.5770834407562329 -2.09
            children [
              Shape {
                appearance PBRAppearance {
                  baseColor 1 0 0
                  roughness 1
                  metalness 0
                }
                geometry Cylinder {
                  height 0.01
                  radius 0.025
                }
              }
            ]
          }
        ]
      }
    }
    Transform {
      translation 0 0 0.0415
      children [
        Shape {
          appearance PBRAppearance {
            baseColor 0.820075 0.364 0.8
            roughness 1
            metalness 0
          }
          geometry Cylinder {
            height 0.08
            radius 0.045
          }
        }
      ]
    }
    Altimeter {
    }
  ]
  contactMaterial "body"
}
TexturedBackgroundLight {
}
